09:34:41 [32mINFO[0m Waiting for model:
  redis-k8s/0 [idle] active:
09:35:00 [32mINFO[0m Waiting for model:
  flask-k8s/0 [idle] active: 
09:35:30 [32mINFO[0m Waiting for model:
  flask-k8s/0 [idle] active: 
  flask-k8s/2 [executing] active: 
  flask-k8s/1 [executing] active: 
09:35:42 [31m[1mERROR[0m Task was destroyed but it is pending!
task: <Task pending name='Task-61' coro=<Connection.keepalive() running at /home/runner/work/paas-charm/paas-charm/.tox/integration/lib/python3.10/site-packages/websockets/asyncio/connection.py:815> wait_for=<Future pending cb=[Task.__wakeup()]>>
09:35:42 [31m[1mERROR[0m Task was destroyed but it is pending!
task: <Task pending name='Task_Pinger' coro=<Connection._pinger() running at /home/runner/work/paas-charm/paas-charm/.tox/integration/lib/python3.10/site-packages/juju/client/connection.py:529> wait_for=<Future pending cb=[Task.__wakeup()]>>
09:35:42 [31m[1mERROR[0m Fatal error on SSL transport
protocol: <asyncio.sslproto.SSLProtocol object at 0x7f1b4a5bb4c0>
transport: <_SelectorSocketTransport closing fd=17>
Traceback (most recent call last):
  File "/usr/lib/python3.10/asyncio/selector_events.py", line 924, in write
    n = self._sock.send(data)
OSError: [Errno 9] Bad file descriptor

During handling of the above exception, another exception occurred:

Traceback (most recent call last):
  File "/usr/lib/python3.10/asyncio/sslproto.py", line 690, in _process_write_backlog
    self._transport.write(chunk)
  File "/usr/lib/python3.10/asyncio/selector_events.py", line 930, in write
    self._fatal_error(exc, 'Fatal write error on socket transport')
  File "/usr/lib/python3.10/asyncio/selector_events.py", line 725, in _fatal_error
    self._force_close(exc)
  File "/usr/lib/python3.10/asyncio/selector_events.py", line 737, in _force_close
    self._loop.call_soon(self._call_connection_lost, exc)
  File "/usr/lib/python3.10/asyncio/base_events.py", line 753, in call_soon
    self._check_closed()
  File "/usr/lib/python3.10/asyncio/base_events.py", line 515, in _check_closed
    raise RuntimeError('Event loop is closed')
RuntimeError: Event loop is closed
09:35:42 [31m[1mERROR[0m Task was destroyed but it is pending!
task: <Task pending name='Task_Receiver' coro=<Connection._receiver() running at /home/runner/work/paas-charm/paas-charm/.tox/integration/lib/python3.10/site-packages/juju/client/connection.py:481> wait_for=<Future pending cb=[Task.__wakeup()]>>
09:35:42 [31m[1mERROR[0m Task was destroyed but it is pending!
task: <Task pending name='Task-1793' coro=<Connection.recv() running at /home/runner/work/paas-charm/paas-charm/.tox/integration/lib/python3.10/site-packages/websockets/asyncio/connection.py:303> wait_for=<Future pending cb=[Task.__wakeup()]> cb=[create_task_with_handler.<locals>._task_result_exp_handler(task_name='tmp', logger=<Logger juju....ection (INFO)>)() at /home/runner/work/paas-charm/paas-charm/.tox/integration/lib/python3.10/site-packages/juju/_jasyncio.py:32]>
09:35:42 [31m[1mERROR[0m Task was destroyed but it is pending!
task: <Task pending name='Task-1794' coro=<Event.wait() running at /usr/lib/python3.10/asyncio/locks.py:214> wait_for=<Future pending cb=[Task.__wakeup()]>>
09:36:00 [32mINFO[0m Waiting for model:
  flask-k8s/0 [idle] active: 
  flask-k8s/2 [idle] active: 
  flask-k8s/1 [idle] active: 
09:36:13 [32mINFO[0m check_correct_celery_stats. Expected schedulers: 1, expected workers 3. Result {'schedulers': ["b'10.1.181.141'"], 'workers': ["b'10.1.181.145'", "b'10.1.181.141'", "b'10.1.181.144'"]}
09:36:14 [32mINFO[0m Waiting for model:
  postgresql-k8s/0 [idle] active: Primary
  django-async-k8s/0 [idle] active: 
  flask-k8s/0 [executing] active: 
  flask-k8s/2 [executing] active: 
  flask-k8s/1 [executing] active: 
  redis-k8s/0 [executing] active: